<?xml version="1.0"?>
<robot xmlns:xacro="http://www.ros.org/wiki/xacro">
    <xacro:include filename="$(find fishbot_description)/urdf/fish_bot/common_intertial.xacro" />
        <xacro:macro name="wheel_xacro" params="wheel_name xyz">
        <!-- 機器人的IMU部件 慣性測量感測器 -->
            <link name="${wheel_name}_link">
            <!-- 部件的外觀描述 -->
            <visual>

                <!-- 沿著自己集合中心的偏移與旋轉量 -->
                <origin xyz="0.0 0.0 0.0" rpy="1.57079 0.0 0.0" />

                <!-- 幾何形狀 -->
                <geometry>
                    <cylinder radius="0.032" length="0.04"/>
                </geometry>

                <!-- 材質顏色 -->
                <material name="yellow">
                    <color rgba="1.0 1.0 0.0 0.8"/>
                </material>
            </visual>
            <collision>
                <!-- 沿著自己集合中心的偏移與旋轉量 -->
                <origin xyz="0.0 0.0 0.0" rpy="1.57079 0.0 0.0" />

                <!-- 幾何形狀 -->
                <geometry>
                    <cylinder radius="0.032" length="0.04"/>
                </geometry>

                <!-- 材質顏色 -->
                <material name="yellow">
                    <color rgba="1.0 1.0 0.0 0.8"/>
                </material>
            </collision>

            <!-- 單位為千克 kg -->
            <xacro:cylinder_inertia m="0.05" r="0.032" h="0.04" />
        </link>

        <!-- 機器人的關節 用於機器人的部件 -->
        <!-- continuous 可轉動關節 -->
        <joint name="${wheel_name}_joint" type="continuous">
            <parent link="base_link"/>
            <child link="${wheel_name}_link"/>
            <origin xyz="${xyz}" rpy="0.0 0.0 0.0"/>
            <!-- axis 沿著某軸旋轉 這裡是沿著y軸旋轉 -->
            <axis xyz="0 1 0"/>
        </joint>

        <gazebo reference="${wheel_name}_link">
            <mu1 value="20.0"/> <!--切向摩擦係數 -->
            <mu2 value="20.0"/> <!--法向摩擦係數-->
            <kp value="1000000000.0"/> <!--鋼度係數-->
            <kd value="1.0"/> <!--阻尼係數-->
        </gazebo>
    </xacro:macro>

</robot>